---
title: 异常
tags: C++
---



> 异常是通过**抛出对象而引发**的，该**对象的类型**决定了应该激活哪个catch的处理代码

```cpp
int func()
{
	throw 0;

	return 1;
}

//异常
void test1()
{
	try
	{
		func();
	}
	catch (char ch)
	{
		cout << "ch" << endl;
	}
	catch (const char* str)
	{
		cout << "str" << endl;
	}
    // i 将被输出，下面的 catch 捕获异常
	catch (int i)
	{
		cout << "i" << endl;
	}
}
```





> 被**选中的处理代码**是调用链中**与该对象类型匹配且离抛出异常位置最近**的那一个

```cpp
int func()
{
	throw 0;

	return 1;
}

//异常
void test1()
{
	try
	{
		func();
	}
	catch (char ch)
	{
		cout << "ch" << endl;
	}
	catch (const char* str)
	{
		cout << "str" << endl;
	}
	catch (int i)
	{
		cout << "test1 i" << endl;
	}
}

void test2()
{
	try
	{
		test1();
	}
	catch (int i)
	{
		cout << "test2 i" << endl;
	}
}

//输出：
test1 i
```

如果将 `test1` 中，`catch(int i)` 注释掉：

```cpp
void test1()
{
	try
	{
		func();
	}
	catch (char ch)
	{
		cout << "ch" << endl;
	}
	catch (const char* str)
	{
		cout << "str" << endl;
	}
	//catch (int i)
	//{
	//	cout << "test1 i" << endl;
	//}
}

void test2()
{
	try
	{
		test1();
	}
	catch (int i)
	{
		cout << "test2 i" << endl;
	}
}
```

输出变为：

```cpp
test2 i
```



> 抛出异常对象后，会生成一个异常对象的拷贝，因为抛出的异常对象可能是一个临时对象，所以会生成s一个拷贝对象，这个拷贝的临时对象会在被catch以后销毁。（这里的处理类似于函数的传值返回）

.

> catch(...)可以捕获任意类型的异常，问题是不知道异常错误是什么。

```cpp
	try
	{
		func();
	}
	catch (char ch)
	{
		cout << "ch" << endl;
	}
	catch (const char* str)
	{
		cout << "str" << endl;
	}
	catch (int i)
	{
		cout << "test1 i" << endl;
	}
	// 可以捕获任意类型的异常，问题是不知道异常错误是什么
	// 如果将 ... 写成第一个，后面的 catch 都没有意义。因此，一般来说，
	// catch(...) 写在 catch 的最后
	catch (...)
	{
		cout << "..." << endl;
	}
```



> 实际中抛出和捕获的匹配原则有个例外，并不都是类型完全匹配，**可以抛出的派生类对象，使用基类捕获** (类似切片)



> 如果当前函数不能处理异常，则退出当前函数栈，在上层调用的函数栈中进行查找。如果到 main 函数，都不能处理，则程序崩溃

**注意：** 最好不要让程序崩溃，可以使用 `catch(...)` 做最终处理。



> 函数调用栈只能向前回溯，不能向后退

最终在哪个函数处理完异常，则在从该函数继续向下执行。

```cpp
void test1()
{
	try
	{
		func();
	}
	catch (char ch)
	{
		cout << "ch" << endl;
	}
	catch (const char* str)
	{
		cout << "str" << endl;
	}
	
	cout << "Go Back Here" << endl;
}

void test2()
{
	try
	{
		test1();
	}
	catch (int i)
	{
		cout << "test2 i" << endl;
	}

	cout << "Not Go Back" << endl;
}

// 输出：
test2 i
Not Go Back
```



>异常的重新抛出：用来释放资源

```cpp
void test1()
{
	int* pi = new int[100];
	try
	{
		func();
	}
	catch (char ch)
	{
		cout << "ch" << endl;
	}
	catch (const char* str)
	{
		cout << "str" << endl;
	}
	catch (...)
	{
		cout << "catch(...)" << endl;
		
		// 释放资源
		delete[] pi;

		// 异常重新抛出
		throw;
	}
	
	delete[] pi;
}

void test2()
{
	try
	{
		test1();
	}
	catch (int i)
	{
		cout << "test2 i" << endl;
	}
}
```





**异常安全：**

- 构造中不要写异常
- 析构中不要写异常
- C++ 经常使用 RAII 来解决在 new & delete （可能造成资源泄露），lock & unlock（可能造成死锁） 使用中抛出的异常。



**异常规范：**

```cpp
void func() throw(A, B, C); // 可能抛出 A，B，C
void func2() throw(std::bad_alloc); // 只可能抛出这一个异常
void fun3() throw(); // 表示不会抛出异常
// 若接口无声明，可能会抛出任何异常
```



> 一般要写两个异常处理函数：
>
> - `exception`
> - `catch(...)`

在用 `catch` 接受异常时，我们使用异常类型的引用或者指针来接受，这样父类引用引用子类对象时，可以调用子类的重写方法：

```cpp
catch(exception& e)
{
    // 查看异常的类型
    e.what();
    ...
}
```



**异常的优缺点：**

**优点：**

- 比错误码更清晰的展示错误信息，更好的定位程序 bug
- 不用像错误码那样层层返回。

**缺点：**

- 导致程序流混乱
- 异常会有一些性能的开销
- C++ 没有垃圾回收机制，资源需要自己管理，容易导致资源泄露，死锁等安全问题。需要使用 RAII 来处理资源的管理问题。

















